Workbook

Sheet Projekt
C2: PROJEKT ZALICZENIOWY
C8: Student1
C9: Student2
C11: Zbiór danych:
C12: Projekt został przygotowany na podstawie danych ze zbioru German Credit Data udostępnionego przez UCI Machine Learning Repository, poniżej znajduje się link do repozytorium:
C14: https://github.com/JLZml/Credit-Scoring-Data-Sets/tree/master/1.%20UCI%20Repository/German
C15: Zbiór danych został przez nas odkodowany, bazując na informacjach zawartych w repozytorium, a następnie zapisany w pliku Excel. Składał się on z 1000 obserwacji dotyczących kredytobiorców pewnego niemieckiego banku. Wybraliśmy z niego zmienne, które zostały przez nas wykorzystane do przykładów zaprezentowanych w projekcie. Ograniczony pod względem liczby zmiennych zbiór został zamieszczony w arkuszu "Dane".

Sheet Dane
A1: k | B1: czas trwania | C1: kwota kredytu | D1: wiek | E1: status plec | F1: mieszkanie | G1: klasa
A2: 1 | B2: 6 | C2: 1169 | D2: 67 | E2: mężczyzna singiel | F2: własność | G2: dobry
A3: 2 | B3: 48 | C3: 5951 | D3: 22 | E3: kobieta | F3: własność | G3: zły
A4: 3 | B4: 12 | C4: 2096 | D4: 49 | E4: mężczyzna singiel | F4: własność | G4: dobry
A5: 4 | B5: 42 | C5: 7882 | D5: 45 | E5: mężczyzna singiel | F5: za darmo | G5: dobry
A6: 5 | B6: 24 | C6: 4870 | D6: 53 | E6: mężczyzna singiel | F6: za darmo | G6: zły
A7: 6 | B7: 36 | C7: 9055 | D7: 35 | E7: mężczyzna singiel | F7: za darmo | G7: dobry
A8: 7 | B8: 24 | C8: 2835 | D8: 53 | E8: mężczyzna singiel | F8: własność | G8: dobry
A9: 8 | B9: 36 | C9: 6948 | D9: 35 | E9: mężczyzna singiel | F9: wynajem | G9: dobry
A10: 9 | B10: 12 | C10: 3059 | D10: 61 | E10: mężczyzna rozwiedziony | F10: własność | G10: dobry
A11: 10 | B11: 30 | C11: 5234 | D11: 28 | E11: mężczyzna żonaty | F11: własność | G11: zły
A12: 11 | B12: 12 | C12: 1295 | D12: 25 | E12: kobieta | F12: wynajem | G12: zły
A13: 12 | B13: 48 | C13: 4308 | D13: 24 | E13: kobieta | F13: wynajem | G13: zły
... A1001: 1000 | B1001: 45 | C1001: 4576 | D1001: 27 | E1001: mężczyzna singiel | F1001: własność | G1001: dobry

Sheet 1.1 Losowanie proste
B2: LOSOWANIE PROSTE ZE ZWRACANIEM - ESTYMACJA PROSTA
B3: Populację generalną stanowi 1000 kredytobiorców z pewnego niemieckiego banku. Badaną cechą jest czas trwania zadłużenia w miesiącach (Y). Wylosowano niezależnie próbę wstępną 200 kredytobiorców, aby oszacować średni czas trwania kredytu z błędem nie większym niż 2 miesiące oraz łączny czas trwania kredytów w populacji.
C8: y
A9: i | B9: k | C9: czas trwania | E9: Najpierw sprawdzono czy liczebność próby wstępnej jest wystarczająca do wyliczenia minimalnej liczebności próby.
A10: 1 | B10: 915 | C10: =VLOOKUP(B10,Dane!$A:$F,2,FALSE) -> 24 | E10: Użyto do tego współczynnika zmienności wariancji z próby wstępnej.
A11: 2 | B11: 612 | C11: =VLOOKUP(B11,Dane!$A:$F,2,FALSE) -> 10 | E11: N | F11: 1000
A12: 3 | B12: 290 | C12: =VLOOKUP(B12,Dane!$A:$F,2,FALSE) -> 24 | E12: n' | F12: 200
A13: 4 | B13: 926 | C13: =VLOOKUP(B13,Dane!$A:$F,2,FALSE) -> 12 | E13: d | F13: 2
A14: 5 | B14: 976 | C14: =VLOOKUP(B14,Dane!$A:$F,2,FALSE) -> 24 | E14: s'² | F14: =_xlfn.VAR.S(C10:C209) -> 124.39638
A15: 6 | B15: 891 | C15: =VLOOKUP(B15,Dane!$A:$F,2,FALSE) -> 27 | E15: β | F15: =KURT(C10:C209)+3 -> 3.7379398
A16: 7 | B16: 817 | C16: =VLOOKUP(B16,Dane!$A:$F,2,FALSE) -> 6 | E16: V(s'²) | F16: =SQRT((F15-((F12-3)/(F12-1)))/F12) -> 0.11721753 | G16: ≤0,2 => zatem liczebność próby wstępnej jest wystarczająca
A17: 8 | B17: 642 | C17: =VLOOKUP(B17,Dane!$A:$F,2,FALSE) -> 15 | E17: n | F17: =ROUNDUP(F11/(1+F11*F13^2/(4*F14)),0) -> 111 | G17: Otrzymano minimalną liczebność próby równą 111, próba wstępna ma 200 obserwacji,
A18: 9 | B18: 912 | C18: =VLOOKUP(B18,Dane!$A:$F,2,FALSE) -> 24 | G18: zatem dalsze wnioskowanie będzie oparte na próbie n = 200.
A19: 10 | B19: 106 | C19: =VLOOKUP(B19,Dane!$A:$F,2,FALSE) -> 24
A20: 11 | B20: 451 | C20: =VLOOKUP(B20,Dane!$A:$F,2,FALSE) -> 36 | E20: Szacowanie średniej:
A21: 12 | B21: 517 | C21: =VLOOKUP(B21,Dane!$A:$F,2,FALSE) -> 6 | E21: n | F21: 200
A22: 13 | B22: 325 | C22: =VLOOKUP(B22,Dane!$A:$F,2,FALSE) -> 18 | E22: ӯ | F22: =AVERAGE(C10:C209) -> 21.16
A23: 14 | B23: 148 | C23: =VLOOKUP(B23,Dane!$A:$F,2,FALSE) -> 12 | E23: s² | F23: =_xlfn.VAR.S(C10:C209) -> 124.39638
A24: 15 | B24: 633 | C24: =VLOOKUP(B24,Dane!$A:$F,2,FALSE) -> 15 | E24: ="D"&_xlfn.UNICHAR(770) & "²(ӯ)" -> D̂²(ӯ) | F24: =(1-1/F11)*F23/F21 -> 0.62135993
A25: 16 | B25: 503 | C25: =VLOOKUP(B25,Dane!$A:$F,2,FALSE) -> 9 | E25: ="D"&_xlfn.UNICHAR(770) & "(ӯ)" -> D̂(ӯ) | F25: =SQRT(F24) -> 0.78826387
A26: 17 | B26: 661 | C26: =VLOOKUP(B26,Dane!$A:$F,2,FALSE) -> 12
A27: 18 | B27: 410 | C27: =VLOOKUP(B27,Dane!$A:$F,2,FALSE) -> 12 | E27: Oszacowano średni czas trwania kredytu na około 21 miesięcy z błędem standardowym wynoszącym około 0,8 miesiąca.
A28: 19 | B28: 435 | C28: =VLOOKUP(B28,Dane!$A:$F,2,FALSE) -> 9
A29: 20 | B29: 150 | C29: =VLOOKUP(B29,Dane!$A:$F,2,FALSE) -> 18 | E29: Szacowanie sumy:
A30: 21 | B30: 226 | C30: =VLOOKUP(B30,Dane!$A:$F,2,FALSE) -> 36 | E30: ŷ | F30: =F22*F11 -> 21160
A31: 22 | B31: 783 | C31: =VLOOKUP(B31,Dane!$A:$F,2,FALSE) -> 12 | E31: ="D"&_xlfn.UNICHAR(770) & "²(ŷ)" -> D̂²(ŷ) | F31: =F24*F11^2 -> 621359.93
A32: 23 | B32: 629 | C32: =VLOOKUP(B32,Dane!$A:$F,2,FALSE) -> 42 | E32: ="D"&_xlfn.UNICHAR(770) & "(ŷ)" -> D̂(ŷ) | F32: =SQRT(F31) -> 788.26387
A33: 24 | B33: 222 | C33: =VLOOKUP(B33,Dane!$A:$F,2,FALSE) -> 12
A34: 25 | B34: 357 | C34: =VLOOKUP(B34,Dane!$A:$F,2,FALSE) -> 12 | E34: Oszacowano łączny czas trwania kredytów na około 21160 miesięcy z błędem standardowym wynoszącym około 788,3 miesięcy.
A35: 26 | B35: 299 | C35: =VLOOKUP(B35,Dane!$A:$F,2,FALSE) -> 18
A36: 27 | B36: 330 | C36: =VLOOKUP(B36,Dane!$A:$F,2,FALSE) -> 6
A37: 28 | B37: 946 | C37: =VLOOKUP(B37,Dane!$A:$F,2,FALSE) -> 48 | E37: Porównanie wariancji z próby otrzymanej z losowania ze zwracaniem z losowaniem bez zwracania.
A38: 29 | B38: 246 | C38: =VLOOKUP(B38,Dane!$A:$F,2,FALSE) -> 24
A39: 30 | B39: 464 | C39: =VLOOKUP(B39,Dane!$A:$F,2,FALSE) -> 12 | F39: =((1-1/F11)-(1-F21/F11))/(1-F21/F11) -> 0.24875
A40: 31 | B40: 339 | C40: =VLOOKUP(B40,Dane!$A:$F,2,FALSE) -> 24
A41: 32 | B41: 784 | C41: =VLOOKUP(B41,Dane!$A:$F,2,FALSE) -> 12 | E41: Zatem losowanie bez zwracania jest o około 24,9% efektywniejsze niż losowanie ze zwracaniem.
A42: 33 | B42: 726 | C42: =VLOOKUP(B42,Dane!$A:$F,2,FALSE) -> 6
A43: 34 | B43: 709 | C43: =VLOOKUP(B43,Dane!$A:$F,2,FALSE) -> 9
A44: 35 | B44: 210 | C44: =VLOOKUP(B44,Dane!$A:$F,2,FALSE) -> 12
A45: 36 | B45: 132 | C45: =VLOOKUP(B45,Dane!$A:$F,2,FALSE) -> 36
...

Sheet lpbz
A1: i | B1: k | C1: czas trwania | D1: kwota kredytu | E1: wiek | F1: klient | G1: losowa
A2: 1 | B2: 608 | C2: 36 | D2: 2671 | E2: 50 | F2: KZ | G2: 0.0035858301
A3: 2 | B3: 388 | C3: 18 | D3: 7374 | E3: 40 | F3: MD | G3: 0.0035985316
A4: 3 | B4: 385 | C4: 30 | D4: 4272 | E4: 26 | F4: MD | G4: 0.0038327247
A5: 4 | B5: 453 | C5: 12 | D5: 2759 | E5: 34 | F5: MD | G5: 0.0058363312
A6: 5 | B6: 169 | C6: 24 | D6: 3972 | E6: 25 | F6: KD | G6: 0.0070139727
A7: 6 | B7: 811 | C7: 8 | D7: 907 | E7: 26 | F7: MD | G7: 0.0090634301
A8: 7 | B8: 564 | C8: 36 | D8: 12389 | E8: 37 | F8: MZ | G8: 0.0097905631
A9: 8 | B9: 802 | C9: 18 | D9: 1795 | E9: 48 | F9: KD | G9: 0.0099935306
A10: 9 | B10: 136 | C10: 12 | D10: 1240 | E10: 38 | F10: KD | G10: 0.010088823
A11: 10 | B11: 597 | C11: 24 | D11: 1442 | E11: 23 | F11: KZ | G11: 0.010774678
A12: 11 | B12: 256 | C12: 60 | D12: 7418 | E12: 27 | F12: MD | G12: 0.010780852
A13: 12 | B13: 255 | C13: 9 | D13: 2030 | E13: 24 | F13: MD | G13: 0.011428858
... A1001: 1000 | B1001: 99 | C1001: 36 | D1001: 2337 | E1001: 36 | F1001: MD | G1001: 0.99797598

Sheet 1.2 Losowanie proste ez
B2: LOSOWANIE PROSTE BEZ ZWRACANIA - ESTYMACJA ZŁOŻONA
B3: Populację generalną stanowi 1000 kredytobiorców z pewnego niemieckiego banku. Badaną cechą jest czas trwania zadłużenia w miesiącach (Y) w zależności od wysokości kwoty kredytu w markach niemieckich (X1). Wylosowano bez zwracania próbę wstępną 300 kredytobiorców, aby oszacować średni czas trwania kredytu (w miesiącach) z błędem nie większym niż 2 miesiące oraz łączny czas trwania kredytów w populacji.
F7: Porównane zostaną 3 różne estymatory służące do szacowania średniej i sumy czasu trwania: estymator prosty, ilorazowy i regresyjny.
C8: y | D8: x1 | F8: Najpierw sprawdzono czy liczebność próby wstępnej jest wystarczająca do wyliczenia minimalnej liczebności próby dla każdego rodzaju estymatorów.
A9: i | B9: k | C9: czas trwania | D9: kwota kredytu | F9: Użyto do tego współczynnika zmienności wariancji z próby wstępnej.
A10: 1 | B10: 608 | C10: 36 | D10: 2671 | F10: N | G10: 1000
A11: 2 | B11: 388 | C11: 18 | D11: 7374 | F11: n' | G11: 300
A12: 3 | B12: 385 | C12: 30 | D12: 4272 | F12: d | G12: 2
A13: 4 | B13: 453 | C13: 12 | D13: 2759 | F13: ="X" & _xlfn.UNICHAR(773) -> X̅ | G13: =AVERAGE(lpbz!D2:D1001) -> 3271.258
A14: 5 | B14: 169 | C14: 24 | D14: 3972
A15: 6 | B15: 811 | C15: 8 | D15: 907 | F15: Dla estymatora prostego:
A16: 7 | B16: 564 | C16: 36 | D16: 12389 | F16: s'² | G16: =_xlfn.VAR.S(C10:C309) -> 154.96878
A17: 8 | B17: 802 | C17: 18 | D17: 1795 | F17: β | G17: =KURT(C10:C309)+3 -> 3.7590578
A18: 9 | B18: 136 | C18: 12 | D18: 1240 | F18: V(s'²) | G18: =SQRT((G17-((G11-3)/(G11-1)))/G11) -> 0.096016435 | H18: ≤0,2 => zatem liczebność próby wstępnej jest wystarczająca
A19: 10 | B19: 597 | C19: 24 | D19: 1442
A20: 11 | B20: 256 | C20: 60 | D20: 7418 | F20: Dla estymatora ilorazowego:
A21: 12 | B21: 255 | C21: 9 | D21: 2030 | F21: ="x" & _xlfn.UNICHAR(773) -> x̅ | G21: =AVERAGE(D10:D309) -> 3341.0333
A22: 13 | B22: 421 | C22: 15 | D22: 3186 | F22: s'x | G22: =_xlfn.STDEV.S(D10:D309) -> 2919.0516
A23: 14 | B23: 573 | C23: 24 | D23: 5433 | F23: ="V(" & "x" & _xlfn.UNICHAR(773) &")" -> V(x̅) | G23: =SQRT(1-(G11/G10))*((G22/G21)/SQRT(G11)) -> 0.042203586 | H23: <0,1 => zatem liczebność próby wstępnej jest wystarczająca
A24: 15 | B24: 294 | C24: 42 | D24: 4796 | F24: ="y" & _xlfn.UNICHAR(773) -> y̅ | G24: =AVERAGE(C10:C309) -> 21.166667
A25: 16 | B25: 17 | C25: 24 | D25: 2424 | F25: s'y | G25: =_xlfn.STDEV.S(C10:C309) -> 12.448646
A26: 17 | B26: 899 | C26: 15 | D26: 2186 | F26: ="V(" & "y" & _xlfn.UNICHAR(773) &")" -> V(y̅) | G26: =SQRT(1-(G11/G10))*((G25/G24)/SQRT(G11)) -> 0.028409137 | H26: <0,1 => zatem liczebność próby wstępnej jest wystarczająca
A27: 18 | B27: 232 | C27: 9 | D27: 2507 | F27: r' | G27: =G24/G21 -> 0.0063353653
A28: 19 | B28: 948 | C28: 12 | D28: 2859 | F28: c'² | G28: {=SUM((C10:C309-G27*D10:D309)^2)/(G11-1)} -> 203.30701
A29: 20 | B29: 744 | C29: 24 | D29: 2483
A30: 21 | B30: 671 | C30: 24 | D30: 4139 | F30: Dla estymatora regresyjnego:
A31: 22 | B31: 204 | C31: 12 | D31: 902 | F31: n' > 50 | G31: Próba wstępna ma więcej niż 50 obserwacji, więc jest wystarczająca.
A32: 23 | B32: 718 | C32: 18 | D32: 1505 | F32: Oszacowania współczynników regresji liniowej:
A33: 24 | B33: 472 | C33: 6 | D33: 448 | G33: b | H33: a
A34: 25 | B34: 940 | C34: 24 | D34: 6842 | G34: {=LINEST(C10:C309,D10:D309,TRUE)} -> 0.0027199637 | H34: 12.079177
A35: 26 | B35: 577 | C35: 12 | D35: 2930 | F35: s'e² | G35: {=SUM((C10:C309-G34*D10:D309-H34)^2)/(G11-1)} -> 91.929721
A36: 27 | B36: 786 | C36: 18 | D36: 1941
A37: 28 | B37: 274 | C37: 48 | D37: 3060
A38: 29 | B38: 703 | C38: 24 | D38: 1377 | F38: Wyznaczenie minimalnej liczebności próby
A39: 30 | B39: 340 | C39: 10 | D39: 1521 | G39: prosty | H39: ilorazowy | I39: regresyjny
A40: 31 | B40: 322 | C40: 24 | D40: 1938 | F40: n | G40: =ROUNDUP(G10/(1+((G10*G12^2)/(4*G16))),0) -> 135 | H40: =ROUNDUP(G10/(1+((G10*G12^2)/(9*G28))),0) -> 314 | I40: =ROUNDUP(G10/(1+((G10*G12^2)/(9*G35))),0) -> 172
A41: 32 | B41: 960 | C41: 24 | D41: 3069
A42: 33 | B42: 176 | C42: 30 | D42: 7485 | F42: W przypadku estymatora prostego i regresyjnego otrzymano, że próba z 300 obserwacjami byłaby wystarczająca,
A43: 34 | B43: 360 | C43: 30 | D43: 2406 | F43: jednak estymator ilorazowy potrzebuje minimalnej liczebności próby na poziomie 314 obserwacji,
A44: 35 | B44: 944 | C44: 4 | D44: 1455 | F44: zatem wylosowane zostaną dodatkowe 20 obserwacji (zamiast 14, dolosowane będzie 6 dodatkowych obserwacji na wszelki wypadek).
...

Sheet 2. Losowanie proste frakcji
B2: LOSOWANIE PROSTE FRAKCJI
B3: Populację generalną stanowi 1000 kredytobiorców z pewnego niemieckiego banku. Celem badania jest uzyskanie szacunku frakcji klientów uznanych za dobrych w populacji. Wylosowano bez zwracania próbę wstępną 200 kredytobiorców i odnotowano ich ocenę (Y), aby oszacować frakcję z błędem nie większym niż 0,05 oraz podać oszacowaną liczbę dobrych klientów w populacji.
C7: y | F7: Najpierw sprawdzono czy liczebność próby wstępnej jest wystarczająca do wyliczenia minimalnej liczebności próby.
A8: i | B8: k | C8: klient | F8: Użyto do tego frakcji dobrych klientów.
A9: 1 | B9: 608 | C9: =VLOOKUP(B9,Dane!$A$1:$G$1001,7,FALSE) -> zły | D9: =IF(C9="dobry",1,0) -> 0 | F9: N | G9: 1000
A10: 2 | B10: 388 | C10: =VLOOKUP(B10,Dane!$A$1:$G$1001,7,FALSE) -> dobry | D10: =IF(C10="dobry",1,0) -> 1 | F10: n' | G10: 200
A11: 3 | B11: 385 | C11: =VLOOKUP(B11,Dane!$A$1:$G$1001,7,FALSE) -> dobry | D11: =IF(C11="dobry",1,0) -> 1 | F11: d | G11: 0.05
A12: 4 | B12: 453 | C12: =VLOOKUP(B12,Dane!$A$1:$G$1001,7,FALSE) -> dobry | D12: =IF(C12="dobry",1,0) -> 1 | F12: p' | G12: =AVERAGE(D9:D208) -> 0.715 | H12: Ponieważ p' jest w przedziale 0,2 <= P <= 0,8 to liczebność próby wstępnej n' > 60 jest wystarczająca do wyznaczenia minimalnej liczebności próby.
A13: 5 | B13: 169 | C13: =VLOOKUP(B13,Dane!$A$1:$G$1001,7,FALSE) -> dobry | D13: =IF(C13="dobry",1,0) -> 1 | F13: est(PQ) | G13: =G12*(1-G12)*(G10/(G10-1)) -> 0.20479899
A14: 6 | B14: 811 | C14: =VLOOKUP(B14,Dane!$A$1:$G$1001,7,FALSE) -> dobry | D14: =IF(C14="dobry",1,0) -> 1 | F14: n | G14: =ROUNDUP(G9/(1+(G9*G11^2)/(4*G13)),0) -> 247
A15: 7 | B15: 564 | C15: =VLOOKUP(B15,Dane!$A$1:$G$1001,7,FALSE) -> zły | D15: =IF(C15="dobry",1,0) -> 0
A16: 8 | B16: 802 | C16: =VLOOKUP(B16,Dane!$A$1:$G$1001,7,FALSE) -> dobry | D16: =IF(C16="dobry",1,0) -> 1 | F16: Otrzymano, że minimalna liczebność próby wynosi 247, zatem dolosowano dodatkowo 50 obserwacji i jeszcze raz zbadano potrzeby związane z wielkością próby.
A17: 9 | B17: 136 | C17: =VLOOKUP(B17,Dane!$A$1:$G$1001,7,FALSE) -> dobry | D17: =IF(C17="dobry",1,0) -> 1
A18: 10 | B18: 597 | C18: =VLOOKUP(B18,Dane!$A$1:$G$1001,7,FALSE) -> zły | D18: =IF(C18="dobry",1,0) -> 0 | F18: N | G18: 1000
A19: 11 | B19: 256 | C19: =VLOOKUP(B19,Dane!$A$1:$G$1001,7,FALSE) -> dobry | D19: =IF(C19="dobry",1,0) -> 1 | F19: n' | G19: 250
A20: 12 | B20: 255 | C20: =VLOOKUP(B20,Dane!$A$1:$G$1001,7,FALSE) -> dobry | D20: =IF(C20="dobry",1,0) -> 1 | F20: d | G20: 0.05
A21: 13 | B21: 421 | C21: =VLOOKUP(B21,Dane!$A$1:$G$1001,7,FALSE) -> dobry | D21: =IF(C21="dobry",1,0) -> 1 | F21: p' | G21: =AVERAGE(D9:D258) -> 0.708 | H21: Ponieważ p' jest w przedziale 0,2 <= P <= 0,8 to liczebność próby wstępnej n' > 60 jest wystarczająca do wyznaczenia minimalnej liczebności próby.
A22: 14 | B22: 573 | C22: =VLOOKUP(B22,Dane!$A$1:$G$1001,7,FALSE) -> dobry | D22: =IF(C22="dobry",1,0) -> 1 | F22: est(PQ) | G22: =G21*(1-G21)*(G19/(G19-1)) -> 0.20756627
A23: 15 | B23: 294 | C23: =VLOOKUP(B23,Dane!$A$1:$G$1001,7,FALSE) -> dobry | D23: =IF(C23="dobry",1,0) -> 1 | F23: n | G23: =ROUNDUP(G18/(1+(G18*G20^2)/(4*G22)),0) -> 250
A24: 16 | B24: 17 | C24: =VLOOKUP(B24,Dane!$A$1:$G$1001,7,FALSE) -> dobry | D24: =IF(C24="dobry",1,0) -> 1
A25: 17 | B25: 899 | C25: =VLOOKUP(B25,Dane!$A$1:$G$1001,7,FALSE) -> dobry | D25: =IF(C25="dobry",1,0) -> 1 | F25: Otrzymano, że minimalna liczebność próby wynosi 250, zatem nasza próba jest wystarczająca do dalszego wnioskowania.
A26: 18 | B26: 232 | C26: =VLOOKUP(B26,Dane!$A$1:$G$1001,7,FALSE) -> dobry | D26: =IF(C26="dobry",1,0) -> 1
A27: 19 | B27: 948 | C27: =VLOOKUP(B27,Dane!$A$1:$G$1001,7,FALSE) -> dobry | D27: =IF(C27="dobry",1,0) -> 1 | F27: Estymacja punktowa frakcji
A28: 20 | B28: 744 | C28: =VLOOKUP(B28,Dane!$A$1:$G$1001,7,FALSE) -> dobry | D28: =IF(C28="dobry",1,0) -> 1 | F28: ="D"&_xlfn.UNICHAR(770) & "²(p)" -> D̂²(p) | G28: =(G18-G19)*G22/(G18*(G19-1)) -> 0.00062519959
A29: 21 | B29: 671 | C29: =VLOOKUP(B29,Dane!$A$1:$G$1001,7,FALSE) -> dobry | D29: =IF(C29="dobry",1,0) -> 1 | F29: ="D"&_xlfn.UNICHAR(770) & "(p)" -> D̂(p) | G29: =SQRT(G28) -> 0.025003992
A30: 22 | B30: 204 | C30: =VLOOKUP(B30,Dane!$A$1:$G$1001,7,FALSE) -> zły | D30: =IF(C30="dobry",1,0) -> 0
A31: 23 | B31: 718 | C31: =VLOOKUP(B31,Dane!$A$1:$G$1001,7,FALSE) -> dobry | D31: =IF(C31="dobry",1,0) -> 1 | F31: Oszacowano frakcję dobrych klientów banku na poziomie 0,708 z możliwością popełnienia błędu średnio o 0,025.
A32: 24 | B32: 472 | C32: =VLOOKUP(B32,Dane!$A$1:$G$1001,7,FALSE) -> zły | D32: =IF(C32="dobry",1,0) -> 0
A33: 25 | B33: 940 | C33: =VLOOKUP(B33,Dane!$A$1:$G$1001,7,FALSE) -> dobry | D33: =IF(C33="dobry",1,0) -> 1 | F33: Przedziałowy szacunek frakcji
A34: 26 | B34: 577 | C34: =VLOOKUP(B34,Dane!$A$1:$G$1001,7,FALSE) -> dobry | D34: =IF(C34="dobry",1,0) -> 1 | F34: 1 - α | G34: 0.95
A35: 27 | B35: 786 | C35: =VLOOKUP(B35,Dane!$A$1:$G$1001,7,FALSE) -> dobry | D35: =IF(C35="dobry",1,0) -> 1 | F35: α | G35: 0.05
A36: 28 | B36: 274 | C36: =VLOOKUP(B36,Dane!$A$1:$G$1001,7,FALSE) -> zły | D36: =IF(C36="dobry",1,0) -> 0 | F36: z | G36: =_xlfn.NORM.S.INV(1-G35/2) -> 1.959964
A37: 29 | B37: 703 | C37: =VLOOKUP(B37,Dane!$A$1:$G$1001,7,FALSE) -> dobry | D37: =IF(C37="dobry",1,0) -> 1
A38: 30 | B38: 340 | C38: =VLOOKUP(B38,Dane!$A$1:$G$1001,7,FALSE) -> dobry | D38: =IF(C38="dobry",1,0) -> 1 | F38: dolna granica | G38: =G21-G36*G29 -> 0.65899308 | I38: Rzeczywista frakcja dobrych klientów na 95% znajduje się w przedziale (0,659;0,757).
A39: 31 | B39: 322 | C39: =VLOOKUP(B39,Dane!$A$1:$G$1001,7,FALSE) -> zły | D39: =IF(C39="dobry",1,0) -> 0 | F39: górna granica | G39: =G21+G36*G29 -> 0.75700692
A40: 32 | B40: 960 | C40: =VLOOKUP(B40,Dane!$A$1:$G$1001,7,FALSE) -> dobry | D40: =IF(C40="dobry",1,0) -> 1
A41: 33 | B41: 176 | C41: =VLOOKUP(B41,Dane!$A$1:$G$1001,7,FALSE) -> zły | D41: =IF(C41="dobry",1,0) -> 0 | F41: Liczba jednostek wyróżnionych w losowaniu prostym
A42: 34 | B42: 360 | C42: =VLOOKUP(B42,Dane!$A$1:$G$1001,7,FALSE) -> zły | D42: =IF(C42="dobry",1,0) -> 0 | F42: Np | G42: =G21*G18 -> 708
A43: 35 | B43: 944 | C43: =VLOOKUP(B43,Dane!$A$1:$G$1001,7,FALSE) -> dobry | D43: =IF(C43="dobry",1,0) -> 1 | F43: ="D"&_xlfn.UNICHAR(770) & "²(p)" -> D̂²(p) | G43: =G28*G18^2 -> 625.19959
A44: 36 | B44: 743 | C44: =VLOOKUP(B44,Dane!$A$1:$G$1001,7,FALSE) -> dobry | D44: =IF(C44="dobry",1,0) -> 1 | F44: ="D"&_xlfn.UNICHAR(770) & "(p)" -> D̂(p) | G44: =SQRT(G43) -> 25.003992
...

Sheet lw
A1: k | B1: czas trwania | C1: kwota kredytu | D1: wiek | E1: status plec | F1: mieszkanie | G1: klasa
A2: 1 | B2: 6 | C2: 1169 | D2: 67 | E2: mężczyzna singiel | F2: własność | G2: dobry
A3: 2 | B3: 48 | C3: 5951 | D3: 22 | E3: kobieta | F3: własność | G3: zły
A4: 3 | B4: 12 | C4: 2096 | D4: 49 | E4: mężczyzna singiel | F4: własność | G4: dobry
A5: 4 | B5: 42 | C5: 7882 | D5: 45 | E5: mężczyzna singiel | F5: za darmo | G5: dobry
A6: 5 | B6: 24 | C6: 4870 | D6: 53 | E6: mężczyzna singiel | F6: za darmo | G6: zły
A7: 6 | B7: 36 | C7: 9055 | D7: 35 | E7: mężczyzna singiel | F7: za darmo | G7: dobry
A8: 7 | B8: 24 | C8: 2835 | D8: 53 | E8: mężczyzna singiel | F8: własność | G8: dobry
A9: 8 | B9: 36 | C9: 6948 | D9: 35 | E9: mężczyzna singiel | F9: wynajem | G9: dobry
A10: 9 | B10: 12 | C10: 3059 | D10: 61 | E10: mężczyzna rozwiedziony | F10: własność | G10: dobry
A11: 10 | B11: 30 | C11: 5234 | D11: 28 | E11: mężczyzna żonaty | F11: własność | G11: zły
A12: 11 | B12: 12 | C12: 1295 | D12: 25 | E12: kobieta | F12: wynajem | G12: zły
A13: 12 | B13: 48 | C13: 4308 | D13: 24 | E13: kobieta | F13: wynajem | G13: zły
... A1001: 1000 | B1001: 45 | C1001: 4576 | D1001: 27 | E1001: mężczyzna singiel | F1001: własność | G1001: dobry

Sheet MD
A1: i | B1: k | C1: klasa | D1: czas trwania | E1: kwota kredytu | F1: wiek | G1: status plec | H1: mieszkanie | I1: losowa
A2: 1 | B2: 249 | C2: dobry | D2: 24 | E2: 1925 | F2: 26 | G2: mężczyzna singiel | H2: własność | I2: 0.00099328329
A3: 2 | B3: 774 | C3: dobry | D3: 24 | E3: 2223 | F3: 52 | G3: mężczyzna singiel | H3: własność | I3: 0.0062152714
A4: 3 | B4: 894 | C4: dobry | D4: 36 | E4: 5800 | F4: 34 | G4: mężczyzna singiel | H4: własność | I4: 0.0078588444
A5: 4 | B5: 124 | C5: dobry | D5: 10 | E5: 781 | F5: 63 | G5: mężczyzna singiel | H5: za darmo | I5: 0.0084110638
A6: 5 | B6: 887 | C6: dobry | D6: 24 | E6: 2825 | F6: 34 | G6: mężczyzna singiel | H6: własność | I6: 0.020488356
A7: 6 | B7: 265 | C7: dobry | D7: 10 | E7: 1231 | F7: 32 | G7: mężczyzna singiel | H7: własność | I7: 0.026310724
A8: 7 | B8: 907 | C8: dobry | D8: 21 | E8: 3763 | F8: 24 | G8: mężczyzna singiel | H8: własność | I8: 0.026703653
A9: 8 | B9: 811 | C9: dobry | D9: 8 | E9: 907 | F9: 26 | G9: mężczyzna żonaty | H9: własność | I9: 0.033348588
A10: 9 | B10: 831 | C10: dobry | D10: 24 | E10: 2375 | F10: 44 | G10: mężczyzna singiel | H10: własność | I10: 0.037695701
A11: 10 | B11: 34 | C11: dobry | D11: 12 | E11: 1264 | F11: 57 | G11: mężczyzna singiel | H11: wynajem | I11: 0.038763829
A12: 11 | B12: 587 | C12: dobry | D12: 9 | E12: 2799 | F12: 36 | G12: mężczyzna singiel | H12: wynajem | I12: 0.039225189
A13: 12 | B13: 561 | C13: dobry | D13: 24 | E13: 2964 | F13: 49 | G13: mężczyzna singiel | H13: za darmo | I13: 0.041061042
... A500: 499 | B500: 104 | C500: dobry | D500: 9 | E500: 1919 | F500: 35 | G500: mężczyzna singiel | H500: wynajem | I500: 0.99834757

Sheet MZ
A1: i | B1: k | C1: klasa | D1: czas trwania | E1: kwota kredytu | F1: wiek | G1: status plec | H1: mieszkanie | I1: losowa
A2: 1 | B2: 553 | C2: zły | D2: 48 | E2: 6999 | F2: 34 | G2: mężczyzna żonaty | H2: własność | I2: 0.0011334509
A3: 2 | B3: 590 | C3: zły | D3: 12 | E3: 2246 | F3: 60 | G3: mężczyzna singiel | H3: własność | I3: 0.0048299448
A4: 3 | B4: 274 | C4: zły | D4: 48 | E4: 3060 | F4: 28 | G4: mężczyzna singiel | H4: własność | I4: 0.012001765
A5: 4 | B5: 399 | C5: zły | D5: 12 | E5: 1223 | F5: 46 | G5: mężczyzna rozwiedziony | H5: wynajem | I5: 0.014587184
A6: 5 | B6: 191 | C6: zły | D6: 24 | E6: 4591 | F6: 54 | G6: mężczyzna singiel | H6: własność | I6: 0.034703088
A7: 6 | B7: 138 | C7: zły | D7: 12 | E7: 766 | F7: 66 | G7: mężczyzna singiel | H7: własność | I7: 0.036917125
A8: 7 | B8: 541 | C8: zły | D8: 12 | E8: 1534 | F8: 23 | G8: mężczyzna żonaty | H8: wynajem | I8: 0.039962116
A9: 8 | B9: 475 | C9: zły | D9: 18 | E9: 1245 | F9: 33 | G9: mężczyzna żonaty | H9: własność | I9: 0.044786046
A10: 9 | B10: 231 | C10: zły | D10: 36 | E10: 4210 | F10: 26 | G10: mężczyzna singiel | H10: własność | I10: 0.046169005
A11: 10 | B11: 598 | C11: zły | D11: 24 | E11: 4241 | F11: 36 | G11: mężczyzna singiel | H11: własność | I11: 0.049477943
A12: 11 | B12: 290 | C12: zły | D12: 24 | E12: 1024 | F12: 48 | G12: mężczyzna żonaty | H12: własność | I12: 0.053256505
A13: 12 | B13: 132 | C13: zły | D13: 36 | E13: 6887 | F13: 29 | G13: mężczyzna singiel | H13: własność | I13: 0.068056855
... A192: 191 | B192: 979 | C192: zły | D192: 24 | E192: 2538 | F192: 47 | G192: mężczyzna singiel | H192: własność | I192: 0.98947508

Sheet KD
A1: i | B1: k | C1: klasa | D1: czas trwania | E1: kwota kredytu | F1: wiek | G1: status plec | H1: mieszkanie | I1: losowa
A2: 1 | B2: 733 | C2: dobry | D2: 8 | E2: 760 | F2: 44 | G2: kobieta | H2: własność | I2: 0.001465756
A3: 2 | B3: 212 | C3: dobry | D3: 36 | E3: 3835 | F3: 45 | G3: kobieta | H3: własność | I3: 0.0073352072
A4: 3 | B4: 706 | C4: dobry | D4: 15 | E4: 5324 | F4: 35 | G4: kobieta | H4: za darmo | I4: 0.013940572
A5: 4 | B5: 538 | C5: dobry | D5: 18 | E5: 3612 | F5: 37 | G5: kobieta | H5: własność | I5: 0.020133869
A6: 5 | B6: 761 | C6: dobry | D6: 15 | E6: 5045 | F6: 59 | G6: kobieta | H6: własność | I6: 0.032058233
A7: 6 | B7: 370 | C7: dobry | D7: 18 | E7: 3001 | F7: 40 | G7: kobieta | H7: wynajem | I7: 0.034007576
A8: 7 | B8: 874 | C8: dobry | D8: 15 | E8: 874 | F8: 24 | G8: kobieta | H8: własność | I8: 0.037331717
A9: 8 | B9: 50 | C9: dobry | D9: 12 | E9: 2073 | F9: 28 | G9: kobieta | H9: własność | I9: 0.039664522
A10: 9 | B10: 576 | C10: dobry | D10: 15 | E10: 2788 | F10: 24 | G10: kobieta | H10: własność | I10: 0.040750155
A11: 10 | B11: 516 | C11: dobry | D11: 6 | E11: 609 | F11: 37 | G11: kobieta | H11: własność | I11: 0.04768875
A12: 11 | B12: 469 | C12: dobry | D12: 33 | E12: 2764 | F12: 26 | G12: kobieta | H12: własność | I12: 0.049726156
A13: 12 | B13: 346 | C13: dobry | D13: 15 | E13: 1459 | F13: 43 | G13: kobieta | H13: własność | I13: 0.052666242
... A202: 201 | B202: 525 | C202: dobry | D202: 18 | E202: 1113 | F202: 26 | G202: kobieta | H202: własność | I202: 0.99908437

Sheet KZ
A1: i | B1: k | C1: klasa | D1: czas trwania | E1: kwota kredytu | F1: wiek | G1: status plec | H1: mieszkanie | I1: losowa
A2: 1 | B2: 843 | C2: zły | D2: 18 | E2: 1943 | F2: 23 | G2: kobieta | H2: własność | I2: 0.0033207095
A3: 2 | B3: 912 | C3: zły | D3: 24 | E3: 4736 | F3: 25 | G3: kobieta | H3: własność | I3: 0.018722149
A4: 3 | B4: 558 | C4: zły | D4: 21 | E4: 5003 | F4: 29 | G4: kobieta | H4: własność | I4: 0.028418802
A5: 4 | B5: 723 | C5: zły | D5: 12 | E5: 1228 | F5: 24 | G5: kobieta | H5: własność | I5: 0.077739703
A6: 5 | B6: 12 | C6: zły | D6: 48 | E6: 4308 | F6: 24 | G6: kobieta | H6: wynajem | I6: 0.10787452
A7: 6 | B7: 608 | C7: zły | D7: 36 | E7: 2671 | F7: 50 | G7: kobieta | H7: za darmo | I7: 0.12008728
A8: 7 | B8: 762 | C8: zły | D8: 18 | E8: 2124 | F8: 24 | G8: kobieta | H8: wynajem | I8: 0.12091199
A9: 8 | B9: 60 | C9: zły | D9: 36 | E9: 6229 | F9: 23 | G9: kobieta | H9: wynajem | I9: 0.14479457
A10: 9 | B10: 532 | C10: zły | D10: 15 | E10: 2631 | F10: 28 | G10: kobieta | H10: wynajem | I10: 0.15033154
A11: 10 | B11: 425 | C11: zły | D11: 12 | E11: 2762 | F11: 25 | G11: kobieta | H11: własność | I11: 0.17464041
A12: 11 | B12: 430 | C12: zły | D12: 18 | E12: 1190 | F12: 55 | G12: kobieta | H12: za darmo | I12: 0.18427153
A13: 12 | B13: 729 | C13: zły | D13: 48 | E13: 6416 | F13: 59 | G13: kobieta | H13: wynajem | I13: 0.18573654
... A110: 109 | B110: 476 | C110: zły | D110: 18 | E110: 3114 | F110: 26 | G110: kobieta | H110: wynajem | I110: 0.99310172

Sheet 3.1 Losowanie warstwowe PROP
B2: LOSOWANIE WARSTWOWE - LOKALIZACJA PROPORCJONALNA
B3: Populację generalną stanowi 1000 kredytobiorców z pewnego niemieckiego banku. Populacja ta została podzielona na 4 warstwy względem płci i oceny klienta (X1). Badaną cechą jest czas trwania zadłużenia klienta w miesiącach (Y). Wylosowano bez zwracania próbę wstępną 200 kredytobiorców stosując lokalizację proporcjonalną próby, aby oszacować średni czas trwania kredytu oraz łączny czas trwania kredytów w populacji z błędem nie większym niż 2 miesiące.
C8: x1 | D8: y
A9: i | B9: k | C9: klient | D9: czas trwania | F9: Struktura populacji | J9: Struktura próby
A10: 1 | B10: 249 | C10: MD | D10: =VLOOKUP('3.1 Losowanie warstwowe PROP'!B10,lw!$A$1:$G$1001,2,FALSE) -> 24 | G10: Płeć | K10: Płeć
A11: 2 | B11: 774 | C11: MD | D11: =VLOOKUP('3.1 Losowanie warstwowe PROP'!B11,lw!$A$1:$G$1001,2,FALSE) -> 24 | F11: klient | G11: M | H11: K | J11: klient | K11: M | L11: K
A12: 3 | B12: 894 | C12: MD | D12: =VLOOKUP('3.1 Losowanie warstwowe PROP'!B12,lw!$A$1:$G$1001,2,FALSE) -> 36 | F12: dobry | G12: =G17/$G$21 -> 0.499 | H12: =G19/$G$21 -> 0.201 | J12: dobry | K12: =I17/$I$21 -> 0.5 | L12: =I19/$I$21 -> 0.2
A13: 4 | B13: 124 | C13: MD | D13: =VLOOKUP('3.1 Losowanie warstwowe PROP'!B13,lw!$A$1:$G$1001,2,FALSE) -> 10 | F13: zły | G13: =G18/$G$21 -> 0.191 | H13: =G20/$G$21 -> 0.109 | J13: zły | K13: =I18/$I$21 -> 0.19 | L13: =I20/$I$21 -> 0.11
A14: 5 | B14: 887 | C14: MD | D14: =VLOOKUP('3.1 Losowanie warstwowe PROP'!B14,lw!$A$1:$G$1001,2,FALSE) -> 24
A15: 6 | B15: 265 | C15: MD | D15: =VLOOKUP('3.1 Losowanie warstwowe PROP'!B15,lw!$A$1:$G$1001,2,FALSE) -> 10 | F15: Wyznaczono wagi i liczebności warstw w próbie oraz wariancje dla poszczególnych warstw.
A16: 7 | B16: 907 | C16: MD | D16: =VLOOKUP('3.1 Losowanie warstwowe PROP'!B16,lw!$A$1:$G$1001,2,FALSE) -> 21 | F16: Warstwa | G16: Nh | H16: Wh | I16: n'h | J16: s'h2
A17: 8 | B17: 811 | C17: MD | D17: =VLOOKUP('3.1 Losowanie warstwowe PROP'!B17,lw!$A$1:$G$1001,2,FALSE) -> 8 | F17: MD | G17: 499 | H17: =G17/$G$21 -> 0.499 | I17: =ROUND(H17*$G$25,0) -> 100 | J17: {=_xlfn.VAR.S(IF($C$10:$C$209=F17,$D$10:$D$209,""))} -> 136.33081
A18: 9 | B18: 831 | C18: MD | D18: =VLOOKUP('3.1 Losowanie warstwowe PROP'!B18,lw!$A$1:$G$1001,2,FALSE) -> 24 | F18: MZ | G18: 191 | H18: =G18/$G$21 -> 0.191 | I18: =ROUND(H18*$G$25,0) -> 38 | J18: {=_xlfn.VAR.S(IF($C$10:$C$209=F18,$D$10:$D$209,""))} -> 177.90114
A19: 10 | B19: 34 | C19: MD | D19: =VLOOKUP('3.1 Losowanie warstwowe PROP'!B19,lw!$A$1:$G$1001,2,FALSE) -> 12 | F19: KD | G19: 201 | H19: =G19/$G$21 -> 0.201 | I19: =ROUND(H19*$G$25,0) -> 40 | J19: {=_xlfn.VAR.S(IF($C$10:$C$209=F19,$D$10:$D$209,""))} -> 88.625
A20: 11 | B20: 587 | C20: MD | D20: =VLOOKUP('3.1 Losowanie warstwowe PROP'!B20,lw!$A$1:$G$1001,2,FALSE) -> 9 | F20: KZ | G20: 109 | H20: =G20/$G$21 -> 0.109 | I20: =ROUND(H20*$G$25,0) -> 22 | J20: {=_xlfn.VAR.S(IF($C$10:$C$209=F20,$D$10:$D$209,""))} -> 208.53896
A21: 12 | B21: 561 | C21: MD | D21: =VLOOKUP('3.1 Losowanie warstwowe PROP'!B21,lw!$A$1:$G$1001,2,FALSE) -> 24 | F21: Suma: | G21: =SUM(G17:G20) -> 1000 | H21: =SUM(H17:H20) -> 1 | I21: =SUM(I17:I20) -> 200
A22: 13 | B22: 934 | C22: MD | D22: =VLOOKUP('3.1 Losowanie warstwowe PROP'!B22,lw!$A$1:$G$1001,2,FALSE) -> 12 | H22: wzór 39
A23: 14 | B23: 515 | C23: MD | D23: =VLOOKUP('3.1 Losowanie warstwowe PROP'!B23,lw!$A$1:$G$1001,2,FALSE) -> 24 | F23: N | G23: 1000 | I23: Wyznaczenie minimalnej liczebności próby
A24: 15 | B24: 8 | C24: MD | D24: =VLOOKUP('3.1 Losowanie warstwowe PROP'!B24,lw!$A$1:$G$1001,2,FALSE) -> 36 | F24: d | G24: 2 | I24: s'w2 | J24: =SUMPRODUCT(J17:J20,H17:H20) -> 142.55256
A25: 16 | B25: 610 | C25: MD | D25: =VLOOKUP('3.1 Losowanie warstwowe PROP'!B25,lw!$A$1:$G$1001,2,FALSE) -> 15 | F25: n' | G25: 200 | I25: nprop | J25: =ROUNDUP(J24/(G24^2/4+J24/G23),0) -> 125
A26: 17 | B26: 40 | C26: MD | D26: =VLOOKUP('3.1 Losowanie warstwowe PROP'!B26,lw!$A$1:$G$1001,2,FALSE) -> 9 | F26: n | G26: 200 | I26: Otrzymano minimalną liczebność próby na poziomie 125 obserwacji, zatem dalsze wnioskowanie będzie oparte na próbie 200 obserwacji.
A27: 18 | B27: 324 | C27: MD | D27: =VLOOKUP('3.1 Losowanie warstwowe PROP'!B27,lw!$A$1:$G$1001,2,FALSE) -> 18
A28: 19 | B28: 158 | C28: MD | D28: =VLOOKUP('3.1 Losowanie warstwowe PROP'!B28,lw!$A$1:$G$1001,2,FALSE) -> 12 | F28: Szacowanie średniej:
A29: 20 | B29: 208 | C29: MD | D29: =VLOOKUP('3.1 Losowanie warstwowe PROP'!B29,lw!$A$1:$G$1001,2,FALSE) -> 12 | F29: ӯw | G29: =AVERAGE(D10:D209) -> 21.43
A30: 21 | B30: 699 | C30: MD | D30: =VLOOKUP('3.1 Losowanie warstwowe PROP'!B30,lw!$A$1:$G$1001,2,FALSE) -> 18 | F30: sw2 | G30: =SUMPRODUCT(H17:H20,J17:J20) -> 142.55256
A31: 22 | B31: 246 | C31: MD | D31: =VLOOKUP('3.1 Losowanie warstwowe PROP'!B31,lw!$A$1:$G$1001,2,FALSE) -> 24 | F31: ="D" & _xlfn.UNICHAR(770) & "²prop(" & "y" & _xlfn.UNICHAR(773) & "w)" -> D̂²prop(y̅w) | G31: =(1-G26/G23)*(G30/G26) -> 0.57021025
A32: 23 | B32: 801 | C32: MD | D32: =VLOOKUP('3.1 Losowanie warstwowe PROP'!B32,lw!$A$1:$G$1001,2,FALSE) -> 24 | F32: ="D" & _xlfn.UNICHAR(770) & "prop(" & "y" & _xlfn.UNICHAR(773) & "w)" -> D̂prop(y̅w) | G32: =SQRT(G31) -> 0.75512267
A33: 24 | B33: 914 | C33: MD | D33: =VLOOKUP('3.1 Losowanie warstwowe PROP'!B33,lw!$A$1:$G$1001,2,FALSE) -> 11
A34: 25 | B34: 519 | C34: MD | D34: =VLOOKUP('3.1 Losowanie warstwowe PROP'!B34,lw!$A$1:$G$1001,2,FALSE) -> 6 | F34: Oszacowano średni czas trwania kredytu na około 21,43 miesięcy z błędem standardowym wynoszącym około 0,76 miesiąca.
A35: 26 | B35: 217 | C35: MD | D35: =VLOOKUP('3.1 Losowanie warstwowe PROP'!B35,lw!$A$1:$G$1001,2,FALSE) -> 18
A36: 27 | B36: 892 | C36: MD | D36: =VLOOKUP('3.1 Losowanie warstwowe PROP'!B36,lw!$A$1:$G$1001,2,FALSE) -> 15 | F36: Szacowanie sumy:
A37: 28 | B37: 609 | C37: MD | D37: =VLOOKUP('3.1 Losowanie warstwowe PROP'!B37,lw!$A$1:$G$1001,2,FALSE) -> 18 | F37: ŷ | G37: =G29*G23 -> 21430
A38: 29 | B38: 548 | C38: MD | D38: =VLOOKUP('3.1 Losowanie warstwowe PROP'!B38,lw!$A$1:$G$1001,2,FALSE) -> 24 | F38: ="D"&_xlfn.UNICHAR(770) & "²(ŷ)" -> D̂²(ŷ) | G38: =G31*G23^2 -> 570210.25
A39: 30 | B39: 719 | C39: MD | D39: =VLOOKUP('3.1 Losowanie warstwowe PROP'!B39,lw!$A$1:$G$1001,2,FALSE) -> 24 | F39: ="D"&_xlfn.UNICHAR(770) & "(ŷ)" -> D̂(ŷ) | G39: =SQRT(G38) -> 755.12267
A40: 31 | B40: 679 | C40: MD | D40: =VLOOKUP('3.1 Losowanie warstwowe PROP'!B40,lw!$A$1:$G$1001,2,FALSE) -> 24
A41: 32 | B41: 32 | C41: MD | D41: =VLOOKUP('3.1 Losowanie warstwowe PROP'!B41,lw!$A$1:$G$1001,2,FALSE) -> 24 | F41: Oszacowano łączny czas trwania kredytów na około 21430 miesięcy z z błędem standardowym wynoszącym około 755,12 miesięcy.
A42: 33 | B42: 340 | C42: MD | D42: =VLOOKUP('3.1 Losowanie warstwowe PROP'!B42,lw!$A$1:$G$1001,2,FALSE) -> 10
A43: 34 | B43: 785 | C43: MD | D43: =VLOOKUP('3.1 Losowanie warstwowe PROP'!B43,lw!$A$1:$G$1001,2,FALSE) -> 20 | F43: Porównanie z losowaniem prostym
A44: 35 | B44: 454 | C44: MD | D44: =VLOOKUP('3.1 Losowanie warstwowe PROP'!B44,lw!$A$1:$G$1001,2,FALSE) -> 24 | F44: s² | G44: =_xlfn.VAR.S(D10:D209) -> 151.78402
A45: 36 | B45: 285 | C45: MD | D45: =VLOOKUP('3.1 Losowanie warstwowe PROP'!B45,lw!$A$1:$G$1001,2,FALSE) -> 24 | F45: ="D" & _xlfn.UNICHAR(770) & "²(" & "y" & _xlfn.UNICHAR(773) & ")" -> D̂²(y̅) | G45: =(1-G26/G23)*(G44/G26) -> 0.60713608
...

Sheet 3.2 Losowanie warstwowe RÓW
B2: LOSOWANIE WARSTWOWE - LOKALIZACJA RÓWNOMIERNA
B3: Populację generalną stanowi 1000 kredytobiorców z pewnego niemieckiego banku. Populacja ta została podzielona na 4 warstwy względem płci i oceny klienta (X1). Badaną cechą jest czas trwania zadłużenia klienta w miesiącach (Y). Wylosowano bez zwracania próbę wstępną 200 kredytobiorców stosując lokalizację równomierną próby, aby oszacować średni czas trwania kredytu oraz łączny czas trwania kredytów w populacji z błędem nie większym niż 2 miesiące.
C8: x1 | D8: y
A9: i | B9: k | C9: klient | D9: czas trwania | F9: Struktura populacji | J9: Struktura próby
A10: 1 | B10: 249 | C10: MD | D10: 24 | G10: Płeć | K10: Płeć
A11: 2 | B11: 774 | C11: MD | D11: 24 | F11: klient | G11: M | H11: K | J11: klient | K11: M | L11: K
A12: 3 | B12: 894 | C12: MD | D12: 36 | F12: dobry | G12: =G17/$G$21 -> 0.499 | H12: =G19/$G$21 -> 0.201 | J12: dobry | K12: =I17/$I$21 -> 0.25 | L12: =I17/$I$21 -> 0.25
A13: 4 | B13: 124 | C13: MD | D13: 10 | F13: zły | G13: =G18/$G$21 -> 0.191 | H13: =G20/$G$21 -> 0.109 | J13: zły | K13: =I18/$I$21 -> 0.25 | L13: =I18/$I$21 -> 0.25
A14: 5 | B14: 887 | C14: MD | D14: 24
A15: 6 | B15: 265 | C15: MD | D15: 10 | F15: Wyznaczono wagi i liczebności warstw w próbie oraz wariancje dla poszczególnych warstw.
A16: 7 | B16: 907 | C16: MD | D16: 21 | F16: Warstwa | G16: Nh | H16: Wh | I16: nh | J16: sh2 | K16: ӯh
A17: 8 | B17: 811 | C17: MD | D17: 8 | F17: MD | G17: 499 | H17: =G17/$G$21 -> 0.499 | I17: =COUNTIF($A$10:$D$209,F17) -> 50 | J17: {=_xlfn.VAR.S(IF($C$10:$C$209=F17,$D$10:$D$209,""))} -> 73.977143 | K17: =AVERAGEIF($C$10:$C$209,F17,$D$10:$D$209) -> 18.32
A18: 9 | B18: 831 | C18: MD | D18: 24 | F18: MZ | G18: 191 | H18: =G18/$G$21 -> 0.191 | I18: =COUNTIF($A$10:$D$209,F18) -> 50 | J18: {=_xlfn.VAR.S(IF($C$10:$C$209=F18,$D$10:$D$209,""))} -> 202.35959 | K18: =AVERAGEIF($C$10:$C$209,F18,$D$10:$D$209) -> 26.26
A19: 10 | B19: 34 | C19: MD | D19: 12 | F19: KD | G19: 201 | H19: =G19/$G$21 -> 0.201 | I19: =COUNTIF($A$10:$D$209,F19) -> 50 | J19: {=_xlfn.VAR.S(IF($C$10:$C$209=F19,$D$10:$D$209,""))} -> 77.688163 | K19: =AVERAGEIF($C$10:$C$209,F19,$D$10:$D$209) -> 17.84
A20: 11 | B20: 587 | C20: MD | D20: 9 | F20: KZ | G20: 109 | H20: =G20/$G$21 -> 0.109 | I20: =COUNTIF($A$10:$D$209,F20) -> 50 | J20: {=_xlfn.VAR.S(IF($C$10:$C$209=F20,$D$10:$D$209,""))} -> 163.60163 | K20: =AVERAGEIF($C$10:$C$209,F20,$D$10:$D$209) -> 24.48
A21: 12 | B21: 561 | C21: MD | D21: 24 | F21: Suma: | G21: =SUM(G17:G20) -> 1000 | H21: =SUM(H17:H20) -> 1 | I21: =SUM(I17:I20) -> 200
A22: 13 | B22: 934 | C22: MD | D22: 12
A23: 14 | B23: 515 | C23: MD | D23: 24 | F23: N | G23: 1000
A24: 15 | B24: 8 | C24: MD | D24: 36 | F24: d | G24: 2
A25: 16 | B25: 610 | C25: MD | D25: 15 | F25: n | G25: 200
A26: 17 | B26: 40 | C26: MD | D26: 9
A27: 18 | B27: 324 | C27: MD | D27: 18 | F27: Szacowanie średniej:
A28: 19 | B28: 158 | C28: MD | D28: 12 | F28: ӯw | G28: =SUMPRODUCT(H17:H20,K17:K20) -> 20.4115
A29: 20 | B29: 208 | C29: MD | D29: 12 | F29: sw2 | G29: =SUMPRODUCT(H17:H20,J17:J20) -> 109.01318
A30: 21 | B30: 699 | C30: MD | D30: 18 | F30: ="D" & _xlfn.UNICHAR(770) & "²(" & "y" & _xlfn.UNICHAR(773) & "w)" -> D̂²(y̅w) | G30: {=SUMPRODUCT((H17:H20^2),(1-I17:I20/G17:G20),(J17:J20/I17:I20))} -> 0.50868869
A31: 22 | B31: 246 | C31: MD | D31: 24 | F31: ="D" & _xlfn.UNICHAR(770) & "(" & "y" & _xlfn.UNICHAR(773) & "w)" -> D̂(y̅w) | G31: =SQRT(G30) -> 0.71322415
A32: 23 | B32: 801 | C32: MD | D32: 24
A33: 24 | B33: 914 | C33: MD | D33: 11 | F33: Oszacowano średni czas trwania kredytu na około 20,41 miesięcy z błędem standardowym wynoszącym około 0,71 miesiąca.
A34: 25 | B34: 519 | C34: MD | D34: 6
A35: 26 | B35: 217 | C35: MD | D35: 18 | F35: Szacowanie sumy:
A36: 27 | B36: 892 | C36: MD | D36: 15 | F36: ŷ | G36: =G28*G23 -> 20411.5
A37: 28 | B37: 609 | C37: MD | D37: 18 | F37: ="D"&_xlfn.UNICHAR(770) & "²(ŷ)" -> D̂²(ŷ) | G37: =G30*G23^2 -> 508688.69
A38: 29 | B38: 548 | C38: MD | D38: 24 | F38: ="D"&_xlfn.UNICHAR(770) & "(ŷ)" -> D̂(ŷ) | G38: =SQRT(G37) -> 713.22415
A39: 30 | B39: 719 | C39: MD | D39: 24
A40: 31 | B40: 679 | C40: MD | D40: 24 | F40: Oszacowano łączny czas trwania kredytów na około 20411,5 miesięcy z błędem standardowym wynoszącym około 713,22 miesięcy.
A41: 32 | B41: 32 | C41: MD | D41: 24
A42: 33 | B42: 340 | C42: MD | D42: 10 | F42: Porównanie z losowaniem prostym
A43: 34 | B43: 785 | C43: MD | D43: 20 | F43: s² | G43: =_xlfn.VAR.S(D10:D209) -> 141.23555
A44: 35 | B44: 454 | C44: MD | D44: 24 | F44: ="D" & _xlfn.UNICHAR(770) & "²(" & "y" & _xlfn.UNICHAR(773) & ")" -> D̂²(y̅) | G44: =(1-G25/G23)*(G43/G25) -> 0.56494221
A45: 36 | B45: 285 | C45: MD | D45: 24
...

Sheet 3.3 Losowanie warstwowe OPT
B2: LOSOWANIE WARSTWOWE - LOKALIZACJA OPTYMALNA NEYMANA
B3: Populację generalną stanowi 1000 kredytobiorców z pewnego niemieckiego banku. Populacja ta została podzielona na 4 warstwy względem płci i oceny klienta (X1). Badaną cechą jest czas trwania zadłużenia klienta w miesiącach (Y). Wylosowano bez zwracania próbę wstępną 50 kredytobiorców stosując lokalizację optymalną Neymana próby, aby oszacować średni czas trwania kredytu oraz łączny czas trwania kredytów w populacji z błędem nie większym niż 2 miesiące.
C8: x1 | D8: y
A9: i | B9: k | C9: klient | D9: czas trwania | F9: Struktura populacji | J9: Struktura próby
A10: 1 | B10: 249 | C10: MD | D10: =VLOOKUP('3.1 Losowanie warstwowe PROP'!B10,lw!$A$1:$G$1001,2,FALSE) -> 24 | G10: Płeć | K10: Płeć
A11: 2 | B11: 774 | C11: MD | D11: =VLOOKUP('3.1 Losowanie warstwowe PROP'!B11,lw!$A$1:$G$1001,2,FALSE) -> 24 | F11: klient | G11: M | H11: K | J11: klient | K11: M | L11: K
A12: 3 | B12: 894 | C12: MD | D12: =VLOOKUP('3.1 Losowanie warstwowe PROP'!B12,lw!$A$1:$G$1001,2,FALSE) -> 36 | F12: dobry | G12: =G17/$G$21 -> 0.499 | H12: =G19/$G$21 -> 0.201 | J12: dobry | K12: =I17/$I$21 -> 0.5 | L12: =I19/$I$21 -> 0.2
A13: 4 | B13: 124 | C13: MD | D13: =VLOOKUP('3.1 Losowanie warstwowe PROP'!B13,lw!$A$1:$G$1001,2,FALSE) -> 10 | F13: zły | G13: =G18/$G$21 -> 0.191 | H13: =G20/$G$21 -> 0.109 | J13: zły | K13: =I18/$I$21 -> 0.2 | L13: =I20/$I$21 -> 0.1
A14: 5 | B14: 887 | C14: MD | D14: =VLOOKUP('3.1 Losowanie warstwowe PROP'!B14,lw!$A$1:$G$1001,2,FALSE) -> 24
A15: 6 | B15: 265 | C15: MD | D15: =VLOOKUP('3.1 Losowanie warstwowe PROP'!B15,lw!$A$1:$G$1001,2,FALSE) -> 10 | F15: Wyznaczono wagi i liczebności warstw w próbie oraz wariancje dla poszczególnych warstw.
A16: 7 | B16: 907 | C16: MD | D16: =VLOOKUP('3.1 Losowanie warstwowe PROP'!B16,lw!$A$1:$G$1001,2,FALSE) -> 21 | F16: Warstwa | G16: Nh | H16: Wh | I16: n'h | J16: s'h | K16: nh | L16: dolosować | M16: ȳh | N16: sh
A17: 8 | B17: 811 | C17: MD | D17: =VLOOKUP('3.1 Losowanie warstwowe PROP'!B17,lw!$A$1:$G$1001,2,FALSE) -> 8 | F17: MD | G17: 499 | H17: =G17/$G$21 -> 0.499 | I17: =ROUND(H17*$G$25,0) -> 25 | J17: {=_xlfn.STDEV.S(IF($C$10:$C$59=F17,$D$10:$D$59,""))} -> 8.3681938 | K17: =ROUND($J$26*H17*J17/$J$24,0) -> 38 | L17: =K17-I17 -> 13 | M17: =AVERAGEIF($C$10:$C$101,F17,$D$10:$D$34) -> 18.157895 | N17: {=_xlfn.STDEV.S(IF($C$10:$C$101=F17,$D$10:$D$101,""))} -> 7.6282771
A18: 9 | B18: 831 | C18: MD | D18: =VLOOKUP('3.1 Losowanie warstwowe PROP'!B18,lw!$A$1:$G$1001,2,FALSE) -> 24 | F18: MZ | G18: 191 | H18: =G18/$G$21 -> 0.191 | I18: =ROUND(H18*$G$25,0) -> 10 | J18: {=_xlfn.STDEV.S(IF($C$10:$C$59=F18,$D$10:$D$59,""))} -> 14.546477 | K18: =ROUND($J$26*H18*J18/$J$24,0) -> 25 | L18: =K18-I18 -> 15 | M18: =AVERAGEIF($C$10:$C$101,F18,$D$10:$D$34) -> 25.88 | N18: {=_xlfn.STDEV.S(IF($C$10:$C$101=F18,$D$10:$D$101,""))} -> 12.524376
A19: 10 | B19: 34 | C19: MD | D19: =VLOOKUP('3.1 Losowanie warstwowe PROP'!B19,lw!$A$1:$G$1001,2,FALSE) -> 12 | F19: KD | G19: 201 | H19: =G19/$G$21 -> 0.201 | I19: =ROUND(H19*$G$25,0) -> 10 | J19: {=_xlfn.STDEV.S(IF($C$10:$C$59=F19,$D$10:$D$59,""))} -> 8.1076096 | K19: =ROUND($J$26*H19*J19/$J$24,0) -> 15 | L19: =K19-I19 -> 5 | M19: =AVERAGEIF($C$10:$C$101,F19,$D$10:$D$34) -> 18.133333 | N19: {=_xlfn.STDEV.S(IF($C$10:$C$101=F19,$D$10:$D$101,""))} -> 8.8225901
A20: 11 | B20: 587 | C20: MD | D20: =VLOOKUP('3.1 Losowanie warstwowe PROP'!B20,lw!$A$1:$G$1001,2,FALSE) -> 9 | F20: KZ | G20: 109 | H20: =G20/$G$21 -> 0.109 | I20: =ROUND(H20*$G$25,0) -> 5 | J20: {=_xlfn.STDEV.S(IF($C$10:$C$59=F20,$D$10:$D$59,""))} -> 13.813037 | K20: =ROUND($J$26*H20*J20/$J$24,0) -> 14 | L20: =K20-I20 -> 9 | M20: =AVERAGEIF($C$10:$C$101,F20,$D$10:$D$34) -> 28.714286 | N20: {=_xlfn.STDEV.S(IF($C$10:$C$101=F20,$D$10:$D$101,""))} -> 14.588871
A21: 12 | B21: 561 | C21: MD | D21: =VLOOKUP('3.1 Losowanie warstwowe PROP'!B21,lw!$A$1:$G$1001,2,FALSE) -> 24 | F21: Suma: | G21: =SUM(G17:G20) -> 1000 | H21: =SUM(H17:H20) -> 1 | I21: =SUM(I17:I20) -> 50 | K21: =SUM(K17:K20) -> 92 | L21: =SUM(L17:L20) -> 42
A22: 13 | B22: 934 | C22: MD | D22: =VLOOKUP('3.1 Losowanie warstwowe PROP'!B22,lw!$A$1:$G$1001,2,FALSE) -> 12
A23: 14 | B23: 515 | C23: MD | D23: =VLOOKUP('3.1 Losowanie warstwowe PROP'!B23,lw!$A$1:$G$1001,2,FALSE) -> 24 | F23: N | G23: 1000 | I23: Wyznaczenie minimalnej liczebności próby
A24: 15 | B24: 8 | C24: MD | D24: =VLOOKUP('3.1 Losowanie warstwowe PROP'!B24,lw!$A$1:$G$1001,2,FALSE) -> 36 | F24: d | G24: 2 | I24: ="s" & _xlfn.UNICHAR(773) & "'" -> s̅' | J24: =SUMPRODUCT(H17:H20,J17:J20) -> 10.089356
A25: 16 | B25: 610 | C25: MD | D25: =VLOOKUP('3.1 Losowanie warstwowe PROP'!B25,lw!$A$1:$G$1001,2,FALSE) -> 15 | F25: n' | G25: 50 | I25: s'w² | J25: {=SUMPRODUCT(H17:H20,J17:J20^2)} -> 109.36851
A26: 17 | B26: 40 | C26: MD | D26: =VLOOKUP('3.1 Losowanie warstwowe PROP'!B26,lw!$A$1:$G$1001,2,FALSE) -> 9 | F26: n | G26: 92 | I26: nopt | J26: =ROUNDUP(J24^2/(G24^2/4+J25/G23),0) -> 92
A27: 18 | B27: 324 | C27: MD | D27: =VLOOKUP('3.1 Losowanie warstwowe PROP'!B27,lw!$A$1:$G$1001,2,FALSE) -> 18 | I27: Otrzymano minimalną liczebność próby na poziomie 92 obserwacji, zatem dolosowane zostaną 42 jednostki, wyznaczone odpowiednio z poszczególnych wartstw.
A28: 19 | B28: 158 | C28: MD | D28: =VLOOKUP('3.1 Losowanie warstwowe PROP'!B28,lw!$A$1:$G$1001,2,FALSE) -> 12 | I28: Dalsze wnioskowanie zostanie przeprowadzone na próbie 92 obserwacji.
A29: 20 | B29: 208 | C29: MD | D29: =VLOOKUP('3.1 Losowanie warstwowe PROP'!B29,lw!$A$1:$G$1001,2,FALSE) -> 12 | F29: Szacowanie średniej:
A30: 21 | B30: 699 | C30: MD | D30: =VLOOKUP('3.1 Losowanie warstwowe PROP'!B30,lw!$A$1:$G$1001,2,FALSE) -> 18 | F30: ȳw | G30: =SUMPRODUCT(H17:H20,M17:M20) -> 20.778527
A31: 22 | B31: 246 | C31: MD | D31: =VLOOKUP('3.1 Losowanie warstwowe PROP'!B31,lw!$A$1:$G$1001,2,FALSE) -> 24 | F31: ="s" & _xlfn.UNICHAR(773) -> s̅ | G31: =SUMPRODUCT(H17:H20,N17:N20) -> 9.5621937
A32: 23 | B32: 801 | C32: MD | D32: =VLOOKUP('3.1 Losowanie warstwowe PROP'!B32,lw!$A$1:$G$1001,2,FALSE) -> 24 | F32: sw² | G32: {=SUMPRODUCT(H17:H20,N17:N20^2)} -> 97.841865
A33: 24 | B33: 914 | C33: MD | D33: =VLOOKUP('3.1 Losowanie warstwowe PROP'!B33,lw!$A$1:$G$1001,2,FALSE) -> 11 | F33: ="D" & _xlfn.UNICHAR(770) & "²opt(" & "y" & _xlfn.UNICHAR(773) & "w)" -> D̂²opt(y̅w) | G33: =(G31^2/G26)-(G32/G23) -> 0.89602279
A34: 25 | B34: 519 | C34: MD | D34: =VLOOKUP('3.1 Losowanie warstwowe PROP'!B34,lw!$A$1:$G$1001,2,FALSE) -> 6 | F34: ="D" & _xlfn.UNICHAR(770) & "opt(" & "y" & _xlfn.UNICHAR(773) & "w)" -> D̂opt(y̅w) | G34: =SQRT(G33) -> 0.9465848
A35: 26 | B35: 553 | C35: MZ | D35: 48
A36: 27 | B36: 590 | C36: MZ | D36: 12 | F36: Oszacowano średni czas trwania kredytu na około 20,78 miesięcy z błędem standardowym wynoszącym około 0,95 miesiąca.
A37: 28 | B37: 274 | C37: MZ | D37: 48
A38: 29 | B38: 399 | C38: MZ | D38: 12 | F38: Szacowanie sumy:
A39: 30 | B39: 191 | C39: MZ | D39: 24 | F39: ŷ | G39: =G23*G30 -> 20778.527
A40: 31 | B40: 138 | C40: MZ | D40: 12 | F40: ="D"&_xlfn.UNICHAR(770) & "²opt(ŷ)" -> D̂²opt(ŷ) | G40: =G33*G23^2 -> 896022.79
A41: 32 | B41: 541 | C41: MZ | D41: 12 | F41: ="D"&_xlfn.UNICHAR(770) & "opt(ŷ)" -> D̂opt(ŷ) | G41: =SQRT(G40) -> 946.5848
A42: 33 | B42: 475 | C42: MZ | D42: 18
A43: 34 | B43: 231 | C43: MZ | D43: 36 | F43: Oszacowano łączny czas trwania kredytów na około 20779 miesięcy z błędem standardowym wynoszącym około 946,58 miesięcy.
A44: 35 | B44: 598 | C44: MZ | D44: 24
A45: 36 | B45: 733 | C45: KD | D45: 8 | F45: Porównanie z losowaniem prostym
...

Sheet 3.4 Losowanie warstwowe POST
B2: LOSOWANIE WARSTWOWE - POSTSTRATYFIKACJA
B3: Populację generalną stanowi 1000 kredytobiorców z pewnego niemieckiego banku. Wylosowano bez zwracania próbę zasadniczą (n = 200). Znana jest struktura kredytobiorców tego banku według oceny klienta i płci. Badaną cechą jest czas trwania zadłużenia klienta w miesiącach (Y). Oszacowany zostanie średni czas trwania kredytu oraz łączny czas trwania kredytów w populacji z błędem nie większym niż 2 miesiące przy pomocy estymatora uwzględniającego warstwowanie po wylosowaniu (poststratyfikacji).
C8: x1 | D8: y
A9: i | B9: k | C9: klient | D9: czas trwania | F9: Struktura populacji | J9: Struktura próby
A10: 1 | B10: 608 | C10: KZ | D10: 36 | G10: Płeć | K10: Płeć
A11: 2 | B11: 388 | C11: MD | D11: 18 | F11: klient | G11: M | H11: K | J11: klient | K11: M | L11: K
A12: 3 | B12: 385 | C12: MD | D12: 30 | F12: dobry | G12: =G17/$G$21 -> 0.499 | H12: =G19/$G$21 -> 0.201 | J12: dobry | K12: =I17/$I$21 -> 0.51 | L12: =I19/$I$21 -> 0.205
A13: 4 | B13: 453 | C13: MD | D13: 12 | F13: zły | G13: =G18/$G$21 -> 0.191 | H13: =G20/$G$21 -> 0.109 | J13: zły | K13: =I18/$I$21 -> 0.195 | L13: =I20/$I$21 -> 0.09
A14: 5 | B14: 169 | C14: KD | D14: 24
A15: 6 | B15: 811 | C15: MD | D15: 8 | F15: Wyznaczono wagi i liczebności warstw w próbie oraz wariancje dla poszczególnych warstw.
A16: 7 | B16: 564 | C16: MZ | D16: 36 | F16: Warstwa | G16: Nh | H16: Wh | I16: nh | J16: sh2 | K16: ȳh
A17: 8 | B17: 802 | C17: KD | D17: 18 | F17: MD | G17: 499 | H17: =G17/$G$21 -> 0.499 | I17: =COUNTIF($A$10:$D$209,F17) -> 102 | J17: {=_xlfn.VAR.S(IF($C$10:$C$209=F17,$D$10:$D$209,""))} -> 144.54213 | K17: =AVERAGEIF($C$10:$C$209,F17,$D$10:$D$209) -> 19.95098
A18: 9 | B18: 136 | C18: KD | D18: 12 | F18: MZ | G18: 191 | H18: =G18/$G$21 -> 0.191 | I18: =COUNTIF($A$10:$D$209,F18) -> 39 | J18: {=_xlfn.VAR.S(IF($C$10:$C$209=F18,$D$10:$D$209,""))} -> 183.39406 | K18: =AVERAGEIF($C$10:$C$209,F18,$D$10:$D$209) -> 27.358974
A19: 10 | B19: 597 | C19: KZ | D19: 24 | F19: KD | G19: 201 | H19: =G19/$G$21 -> 0.201 | I19: =COUNTIF($A$10:$D$209,F19) -> 41 | J19: {=_xlfn.VAR.S(IF($C$10:$C$209=F19,$D$10:$D$209,""))} -> 82.787805 | K19: =AVERAGEIF($C$10:$C$209,F19,$D$10:$D$209) -> 16.634146
A20: 11 | B20: 256 | C20: MD | D20: 60 | F20: KZ | G20: 109 | H20: =G20/$G$21 -> 0.109 | I20: =COUNTIF($A$10:$D$209,F20) -> 18 | J20: {=_xlfn.VAR.S(IF($C$10:$C$209=F20,$D$10:$D$209,""))} -> 185.29412 | K20: =AVERAGEIF($C$10:$C$209,F20,$D$10:$D$209) -> 28
A21: 12 | B21: 255 | C21: MD | D21: 9 | F21: Suma: | G21: =SUM(G17:G20) -> 1000 | H21: =SUM(H17:H20) -> 1 | I21: =SUM(I17:I20) -> 200
A22: 13 | B22: 421 | C22: KD | D22: 15
A23: 14 | B23: 573 | C23: KD | D23: 24 | F23: N | G23: 1000
A24: 15 | B24: 294 | C24: MD | D24: 42 | F24: d | G24: 2
A25: 16 | B25: 17 | C25: MD | D25: 24 | F25: n | G25: 200
A26: 17 | B26: 899 | C26: KD | D26: 15
A27: 18 | B27: 232 | C27: MD | D27: 9 | F27: Szacowanie średniej:
A28: 19 | B28: 948 | C28: MD | D28: 12 | F28: ȳpost | G28: =SUMPRODUCT(K17:K20,H17:H20) -> 21.576567
A29: 20 | B29: 744 | C29: MD | D29: 24 | F29: s²w | G29: =SUMPRODUCT(H17:H20,J17:J20) -> 143.9922
A30: 21 | B30: 671 | C30: MD | D30: 24 | F30: ="D" & _xlfn.UNICHAR(770) & "²prop(" & "y" & _xlfn.UNICHAR(773) & "w)" -> D̂²prop(y̅w) | G30: =(1-G25/G23)*G29/G25 -> 0.57596878
A31: 22 | B31: 204 | C31: MZ | D31: 12 | F31: ="D" & _xlfn.UNICHAR(770) & "²post(" & "y" & _xlfn.UNICHAR(773) & "post)" -> D̂²post(y̅post) | G31: {=G30+(1/(G25^2)-1/(G25*G23))*SUMPRODUCT(1-H17:H20,J17:J20)} -> 0.5850093
A32: 23 | B32: 718 | C32: MD | D32: 18 | F32: ="D" & _xlfn.UNICHAR(770) & "post(" & "y" & _xlfn.UNICHAR(773) & "post)" -> D̂post(y̅post) | G32: =SQRT(G31) -> 0.76485901
A33: 24 | B33: 472 | C33: KZ | D33: 6
A34: 25 | B34: 940 | C34: MD | D34: 24 | F34: Oszacowano średni czas trwania kredytu na około 21,58 miesięcy z błędem standardowym wynoszącym około 0,76 miesiąca.
A35: 26 | B35: 577 | C35: KD | D35: 12
A36: 27 | B36: 786 | C36: MD | D36: 18 | F36: Szacowanie sumy:
A37: 28 | B37: 274 | C37: MZ | D37: 48 | F37: ŷ | G37: =G28*G23 -> 21576.567
A38: 29 | B38: 703 | C38: KD | D38: 24 | F38: ="D"&_xlfn.UNICHAR(770) & "²(ŷ)" -> D̂²(ŷ) | G38: =G31*G23^2 -> 585009.3
A39: 30 | B39: 340 | C39: MD | D39: 10 | F39: ="D"&_xlfn.UNICHAR(770) & "(ŷ)" -> D̂(ŷ) | G39: =SQRT(G38) -> 764.85901
A40: 31 | B40: 322 | C40: MZ | D40: 24
A41: 32 | B41: 960 | C41: MD | D41: 24 | F41: Oszacowano łączny czas trwania kredytów na około 21576,57 miesięcy z błędem standardowym wynoszącym około 764,86 miesięcy.
A42: 33 | B42: 176 | C42: KZ | D42: 30
A43: 34 | B43: 360 | C43: KZ | D43: 30 | F43: Porównanie z losowaniem prostym
A44: 35 | B44: 944 | C44: MD | D44: 4 | F44: s² | G44: =_xlfn.VAR.S(D10:D209) -> 157.50392
A45: 36 | B45: 743 | C45: MD | D45: 21 | F45: ="D" & _xlfn.UNICHAR(770) & "²(" & "y" & _xlfn.UNICHAR(773) & ")" -> D̂²(y̅) | G45: =(1-G25/G23)*(G44/G25) -> 0.63001568
...

Sheet lz
A1: i | B1: k | C1: czas trwania | D1: kwota kredytu | E1: wiek | F1: klient | G1: losowa | H1: zespół
A2: 1 | B2: 608 | C2: 36 | D2: 2671 | E2: 50 | F2: KZ | G2: 0.0035858301 | H2: 1 | N2: Wybór zespołów do próby (lpbz)
A3: 2 | B3: 388 | C3: 18 | D3: 7374 | E3: 40 | F3: MD | G3: 0.0035985316 | H3: 2 | M3: 1 | N3: 15 | O3: 0.047553014
A4: 3 | B4: 385 | C4: 30 | D4: 4272 | E4: 26 | F4: MD | G4: 0.0038327247 | H4: 3 | M4: 2 | N4: 29 | O4: 0.050442139
A5: 4 | B5: 453 | C5: 12 | D5: 2759 | E5: 34 | F5: MD | G5: 0.0058363312 | H5: 4 | M5: 3 | N5: 46 | O5: 0.078441363
A6: 5 | B6: 169 | C6: 24 | D6: 3972 | E6: 25 | F6: KD | G6: 0.0070139727 | H6: 5 | M6: 4 | N6: 38 | O6: 0.081155664
A7: 6 | B7: 811 | C7: 8 | D7: 907 | E7: 26 | F7: MD | G7: 0.0090634301 | H7: 6 | M7: 5 | N7: 4 | O7: 0.092977412
A8: 7 | B8: 564 | C8: 36 | D8: 12389 | E8: 37 | F8: MZ | G8: 0.0097905631 | H8: 7 | M8: 6 | N8: 11 | O8: 0.094294055
A9: 8 | B9: 802 | C9: 18 | D9: 1795 | E9: 48 | F9: KD | G9: 0.0099935306 | H9: 8 | M9: 7 | N9: 35 | O9: 0.096350249
A10: 9 | B10: 136 | C10: 12 | D10: 1240 | E10: 38 | F10: KD | G10: 0.010088823 | H10: 9 | M10: 8 | N10: 23 | O10: 0.10193649
A11: 10 | B11: 597 | C11: 24 | D11: 1442 | E11: 23 | F11: KZ | G11: 0.010774678 | H11: 10 | M11: 9 | N11: 12 | O11: 0.10903928
A12: 11 | B12: 256 | C12: 60 | D12: 7418 | E12: 27 | F12: MD | G12: 0.010780852 | H12: 11 | M12: 10 | N12: 34 | O12: 0.11374347
A13: 12 | B13: 255 | C13: 9 | D13: 2030 | E13: 24 | F13: MD | G13: 0.011428858 | H13: 12 | M13: 11 | N13: 27 | O13: 0.16110753
A14: 13 | B14: 421 | C14: 15 | D14: 3186 | E14: 20 | F14: KD | G14: 0.012295428 | H14: 13 | M14: 12 | N14: 9 | O14: 0.17547957
... A18: 17 | B18: 899 | C18: 15 | D18: 2186 | E18: 33 | F18: KD | G18: 0.01630821 | H18: 17 | M18: 16 | N18: 49 | O18: 0.29334818
A19: 18 | B19: 232 | C19: 9 | D19: 2507 | E19: 51 | F19: MD | G19: 0.01830598 | H19: 18 | N19: 42 | O19: 0.33124058
A20: 19 | B20: 948 | C20: 12 | D20: 2859 | E20: 38 | F20: MD | G20: 0.020273635 | H20: 19 | N20: 24 | O20: 0.3758247
A21: 20 | B21: 744 | C21: 24 | D21: 2483 | E21: 22 | F21: MD | G21: 0.020381165 | H21: 20 | N21: 37 | O21: 0.3794911
A22: 21 | B22: 671 | C22: 24 | D22: 4139 | E22: 27 | F22: MD | G22: 0.022536083 | H22: 21 | N22: 1 | O22: 0.44101999
A23: 22 | B23: 204 | C23: 12 | D23: 902 | E23: 21 | F23: MZ | G23: 0.023384559 | H23: 22 | N23: 7 | O23: 0.44357533
A24: 23 | B24: 718 | C24: 18 | D24: 1505 | E24: 32 | F24: MD | G24: 0.024732791 | H24: 23 | N24: 40 | O24: 0.46271647
A25: 24 | B25: 472 | C25: 6 | D25: 448 | E25: 23 | F25: KZ | G25: 0.025952696 | H25: 24 | N25: 19 | O25: 0.47971054
A26: 25 | B26: 940 | C26: 24 | D26: 6842 | E26: 46 | F26: MD | G26: 0.028563275 | H26: 25 | N26: 41 | O26: 0.53689261
A27: 26 | B27: 577 | C27: 12 | D27: 2930 | E27: 27 | F27: KD | G27: 0.02996726 | H27: 26 | N27: 2 | O27: 0.54301786
A28: 27 | B28: 786 | C28: 18 | D28: 1941 | E28: 35 | F28: MD | G28: 0.031161762 | H28: 27 | N28: 8 | O28: 0.58057067
A29: 28 | B29: 274 | C29: 48 | D29: 3060 | E29: 28 | F29: MZ | G29: 0.031435211 | H29: 28 | N29: 25 | O29: 0.59184717
A30: 29 | B30: 703 | C30: 24 | D30: 1377 | E30: 47 | F30: KD | G30: 0.031472221 | H30: 29 | N30: 21 | O30: 0.5973088
... A52: 51 | B52: 277 | C52: 18 | D52: 2404 | E52: 26 | F52: KD | G52: 0.060009862 | H52: 1 | N52: 30 | O52: 0.99148216
A53: 52 | B53: 275 | C53: 30 | D53: 11998 | E53: 34 | F53: MZ | G53: 0.060175866 | H53: 2
A54: 53 | B54: 898 | C54: 12 | D54: 1592 | E54: 35 | F54: KD | G54: 0.0605159 | H54: 3
A55: 54 | B55: 934 | C55: 12 | D55: 522 | E55: 42 | F55: MD | G55: 0.060678577 | H55: 4
A56: 55 | B56: 762 | C56: 18 | D56: 2124 | E56: 24 | F56: KZ | G56: 0.060773678 | H56: 5
A57: 56 | B57: 278 | C57: 12 | D57: 1262 | E57: 49 | F57: MD | G57: 0.062136001 | H57: 6
A58: 57 | B58: 27 | C58: 6 | D58: 426 | E58: 39 | F58: MD | G58: 0.062460567 | H58: 7
A59: 58 | B59: 327 | C59: 12 | D59: 5801 | E59: 49 | F59: MD | G59: 0.062908329 | H59: 8
A60: 59 | B60: 961 | C60: 6 | D60: 1740 | E60: 30 | F60: MD | G60: 0.063454021 | H60: 9
A61: 60 | B61: 118 | C61: 10 | D61: 2132 | E61: 27 | F61: KD | G61: 0.063770005 | H61: 10
A62: 61 | B62: 402 | C62: 18 | D62: 1887 | E62: 28 | F62: MD | G62: 0.06385887 | H62: 11
A63: 62 | B63: 391 | C63: 18 | D63: 1820 | E63: 30 | F63: MD | G63: 0.064908087 | H63: 12
A64: 63 | B64: 95 | C64: 12 | D64: 1318 | E64: 54 | F64: MD | G64: 0.066693446 | H64: 13
...

Sheet 4.1 Losowanie zespołowe RÓW
B2: LOSOWANIE ZESPOŁOWE - PRÓBA RÓWNOLICZNA
B3: Populację generalną stanowi 1000 kredytobiorców z pewnego niemieckiego banku podzielonych na 50 równych, 20-osobowych grup. Badaną cechą jest czas trwania zadłużenia klienta w miesiącach (Y). Wylosowano bez zwracania próbę wstępną składającą się z 10 grup, aby oszacować średni czas trwania kredytu oraz łączny czas trwania kredytów w populacji z błędem nie większym niż 2 miesiące.
C8: Y | D8: M
A9: i | B9: k | C9: czas trwania | D9: grupa | F9: Wyznaczono sumy i średnie czasu trwania kredytów z odpowiednich grup.
A10: 1 | B10: 453 | C10: 12 | D10: 4 | F10: grupa (i) | G10: ŷi | H10: ȳi
A11: 2 | B11: 934 | C11: 12 | D11: 4 | F11: 4 | G11: =SUMIF($D$10:$D$209,F11,$C$10:$C$209) -> 360 | H11: =G11/$G$26 -> 18
A12: 3 | B12: 508 | C12: 15 | D12: 4 | F12: 11 | G12: =SUMIF($D$10:$D$209,F12,$C$10:$C$209) -> 470 | H12: =G12/$G$26 -> 23.5
A13: 4 | B13: 664 | C13: 6 | D13: 4 | F13: 12 | G13: =SUMIF($D$10:$D$209,F13,$C$10:$C$209) -> 525 | H13: =G13/$G$26 -> 26.25
A14: 5 | B14: 804 | C14: 12 | D14: 4 | F14: 15 | G14: =SUMIF($D$10:$D$209,F14,$C$10:$C$209) -> 436 | H14: =G14/$G$26 -> 21.8
A15: 6 | B15: 237 | C15: 6 | D15: 4 | F15: 23 | G15: =SUMIF($D$10:$D$209,F15,$C$10:$C$209) -> 516 | H15: =G15/$G$26 -> 25.8
A16: 7 | B16: 211 | C16: 9 | D16: 4 | F16: 29 | G16: =SUMIF($D$10:$D$209,F16,$C$10:$C$209) -> 441 | H16: =G16/$G$26 -> 22.05
A17: 8 | B17: 775 | C17: 12 | D17: 4 | F17: 34 | G17: =SUMIF($D$10:$D$209,F17,$C$10:$C$209) -> 412 | H17: =G17/$G$26 -> 20.6
A18: 9 | B18: 251 | C18: 6 | D18: 4 | F18: 35 | G18: =SUMIF($D$10:$D$209,F18,$C$10:$C$209) -> 411 | H18: =G18/$G$26 -> 20.55
A19: 10 | B19: 331 | C19: 24 | D19: 4 | F19: 38 | G19: =SUMIF($D$10:$D$209,F19,$C$10:$C$209) -> 324 | H19: =G19/$G$26 -> 16.2
A20: 11 | B20: 416 | C20: 36 | D20: 4 | F20: 46 | G20: =SUMIF($D$10:$D$209,F20,$C$10:$C$209) -> 422 | H20: =G20/$G$26 -> 21.1
A21: 12 | B21: 410 | C21: 12 | D21: 4
A22: 13 | B22: 643 | C22: 15 | D22: 4 | F22: M | G22: 1000
A23: 14 | B23: 858 | C23: 15 | D23: 4 | F23: N | G23: 50
A24: 15 | B24: 651 | C24: 48 | D24: 4 | F24: m | G24: 200
A25: 16 | B25: 737 | C25: 24 | D25: 4 | F25: n' | G25: 10
A26: 17 | B26: 641 | C26: 18 | D26: 4 | F26: ="M" & _xlfn.UNICHAR(773) -> M̅ | G26: =G22/G23 -> 20
A27: 18 | B27: 372 | C27: 18 | D27: 4 | F27: d | G27: 2
A28: 19 | B28: 808 | C28: 12 | D28: 4 | F28: s'z² | G28: {=(1/(G25-1))*SUM((G11:G20-AVERAGE(G11:G20))^2)} -> 3892.6778
A29: 20 | B29: 334 | C29: 48 | D29: 4 | F29: n | G29: =ROUNDUP(G23/(1+G23*(G26^2)*(G27^2)/(9*G28)),0) -> 16 | H29: Otrzymaliśmy, że minimalna liczebność próby to 16 zespołów,
A30: 21 | B30: 256 | C30: 60 | D30: 11 | H30: dlatego dolosowujemy 6 dodatkowych zespołów.
A31: 22 | B31: 402 | C31: 18 | D31: 11
A32: 23 | B32: 920 | C32: 24 | D32: 11 | F32: Wyznaczono sumy i średnie czasu trwania kredytów z odpowiednich grup.
A33: 24 | B33: 523 | C33: 48 | D33: 11 | F33: grupa (i) | G33: ŷi | H33: ȳi
A34: 25 | B34: 184 | C34: 24 | D34: 11 | F34: 4 | G34: =SUMIF($D$10:$D$329,F34,$C$10:$C$329) -> 360 | H34: =G34/$G$26 -> 18
A35: 26 | B35: 871 | C35: 36 | D35: 11 | F35: 11 | G35: =SUMIF($D$10:$D$329,F35,$C$10:$C$329) -> 470 | H35: =G35/$G$26 -> 23.5
A36: 27 | B36: 511 | C36: 12 | D36: 11 | F36: 12 | G36: =SUMIF($D$10:$D$329,F36,$C$10:$C$329) -> 525 | H36: =G36/$G$26 -> 26.25
A37: 28 | B37: 393 | C37: 36 | D37: 11 | F37: 15 | G37: =SUMIF($D$10:$D$329,F37,$C$10:$C$329) -> 436 | H37: =G37/$G$26 -> 21.8
A38: 29 | B38: 880 | C38: 30 | D38: 11 | F38: 23 | G38: =SUMIF($D$10:$D$329,F38,$C$10:$C$329) -> 516 | H38: =G38/$G$26 -> 25.8
A39: 30 | B39: 714 | C39: 9 | D39: 11 | F39: 29 | G39: =SUMIF($D$10:$D$329,F39,$C$10:$C$329) -> 441 | H39: =G39/$G$26 -> 22.05
A40: 31 | B40: 876 | C40: 11 | D40: 11 | F40: 34 | G40: =SUMIF($D$10:$D$329,F40,$C$10:$C$329) -> 412 | H40: =G40/$G$26 -> 20.6
A41: 32 | B41: 679 | C41: 24 | D41: 11 | F41: 35 | G41: =SUMIF($D$10:$D$329,F41,$C$10:$C$329) -> 411 | H41: =G41/$G$26 -> 20.55
A42: 33 | B42: 824 | C42: 8 | D42: 11 | F42: 38 | G42: =SUMIF($D$10:$D$329,F42,$C$10:$C$329) -> 324 | H42: =G42/$G$26 -> 16.2
A43: 34 | B43: 222 | C43: 12 | D43: 11 | F43: 46 | G43: =SUMIF($D$10:$D$329,F43,$C$10:$C$329) -> 422 | H43: =G43/$G$26 -> 21.1
A44: 35 | B44: 88 | C44: 36 | D44: 11 | F44: 9 | G44: =SUMIF($D$10:$D$329,F44,$C$10:$C$329) -> 399 | H44: =G44/$G$26 -> 19.95
A45: 36 | B45: 917 | C45: 10 | D45: 11 | F45: 17 | G45: =SUMIF($D$10:$D$329,F45,$C$10:$C$329) -> 412 | H45: =G45/$G$26 -> 20.6
...

Sheet lz2
A1: i | B1: k | C1: czas trwania | D1: kwota kredytu | E1: wiek | F1: klient | G1: losowa | H1: zespoły wstępne | I1: zespół
